
*************

Tue May 9 15:40:02 UTC 2023
7PQTU2BLNNRJX4N5S6ZQKK6FAQCF7XZY
900815

*************

Wed May 10 03:23:01 UTC 2023
7PQTU2BLNNRJX4N5S6ZQKK6FAQCF7XZY
070132
python3: can't open file '/home/ec2-user/kc_closeStraddle.py': [Errno 2] No such file or directory
  % Total    % Received % Xferd  Average Speed   Time    Time     Time  Current
                                 Dload  Upload   Total   Spent    Left  Speed
  0     0    0     0    0     0      0      0 --:--:-- --:--:-- --:--:--     0
*************

  0     0    0     0    0     0      0      0 --:--:--  0:00:01 --:--:--     0Thu May 11 03:23:06 UTC 2023
100  463k    0  463k    0     0   222k      0 --:--:--  0:00:02 --:--:--  222k100 4835k    0 4835k    0     0  1550k      0 --:--:--  0:00:03 --:--:-- 1550k100 6825k    0 6825k    0     0  1878k      0 --:--:--  0:00:03 --:--:-- 1878k
7PQTU2BLNNRJX4N5S6ZQKK6FAQCF7XZY
879022
  % Total    % Received % Xferd  Average Speed   Time    Time     Time  Current
                                 Dload  Upload   Total   Spent    Left  Speed
  0     0    0     0    0     0      0      0 --:--:-- --:--:-- --:--:--     0
*************

Fri May 12 03:23:11 UTC 2023
  0     0    0     0    0     0      0      0 --:--:--  0:00:01 --:--:--     0100 1571k    0 1571k    0     0   610k      0 --:--:--  0:00:02 --:--:--  610k100 4537k    0 4537k    0     0  1273k      0 --:--:--  0:00:03 --:--:-- 1273k100 6892k    0 6892k    0     0  1671k      0 --:--:--  0:00:04 --:--:-- 1671k
7PQTU2BLNNRJX4N5S6ZQKK6FAQCF7XZY
162272

*************

Sat May 13 03:23:05 UTC 2023
  % Total    % Received % Xferd  Average Speed   Time    Time     Time  Current
                                 Dload  Upload   Total   Spent    Left  Speed
  0     0    0     0    0     0      0      0 --:--:-- --:--:-- --:--:--     0  0     0    0     0    0     0      0      0 --:--:--  0:00:02 --:--:--     0  0     0    0     0    0     0      0      0 --:--:--  0:00:03 --:--:--     0100 21405    0 21405    0     0   5252      0 --:--:--  0:00:04 --:--:--  5254100  583k    0  583k    0     0   130k      0 --:--:--  0:00:04 --:--:--  130k100 3218k    0 3218k    0     0   583k      0 --:--:--  0:00:05 --:--:--  583k100 6479k    0 6479k    0     0  1001k      0 --:--:--  0:00:06 --:--:-- 1476k100 6910k    0 6910k    0     0  1048k      0 --:--:--  0:00:06 --:--:-- 2110k
7PQTU2BLNNRJX4N5S6ZQKK6FAQCF7XZY
047593
Traceback (most recent call last):
  File "/home/ec2-user/kc_makeStrangle.py", line 94, in place_order
    orderId = kite.place_order(
  File "/home/ec2-user/.local/lib/python3.9/site-packages/kiteconnect/connect.py", line 360, in place_order
    return self._post("order.place",
  File "/home/ec2-user/.local/lib/python3.9/site-packages/kiteconnect/connect.py", line 855, in _post
    return self._request(route, "POST", url_args=url_args, params=params, is_json=is_json, query_params=query_params)
  File "/home/ec2-user/.local/lib/python3.9/site-packages/kiteconnect/connect.py", line 927, in _request
    raise exp(data["message"], code=r.status_code)
kiteconnect.exceptions.InputException: Markets are closed right now. Use GTT for placing long standing orders instead. [Read more.](https://support.zerodha.com/category/trading-and-markets/gtt/articles/what-is-the-good-till-triggered-gtt-feature)

During handling of the above exception, another exception occurred:

Traceback (most recent call last):
  File "/home/ec2-user/kc_makeStrangle.py", line 112, in <module>
    place_order(symbol_ce, 0, quantity, kite.TRANSACTION_TYPE_SELL, KiteConnect.EXCHANGE_NFO, KiteConnect.PRODUCT_NRML, KiteConnect.ORDER_TYPE_MARKET)
  File "/home/ec2-user/kc_makeStrangle.py", line 107, in place_order
    logger.error('Order placement failed: %s', e.message)
AttributeError: 'InputException' object has no attribute 'message'

*************

Sun May 14 03:23:04 UTC 2023
  % Total    % Received % Xferd  Average Speed   Time    Time     Time  Current
                                 Dload  Upload   Total   Spent    Left  Speed
  0     0    0     0    0     0      0      0 --:--:-- --:--:-- --:--:--     0  0     0    0     0    0     0      0      0 --:--:--  0:00:01 --:--:--     0100 56688    0 56688    0     0  28930      0 --:--:--  0:00:01 --:--:-- 28937100  873k    0  873k    0     0   341k      0 --:--:--  0:00:02 --:--:--  341k100 3017k    0 3017k    0     0   829k      0 --:--:--  0:00:03 --:--:--  829k100 6105k    0 6105k    0     0  1341k      0 --:--:--  0:00:04 --:--:-- 1341k100 6910k    0 6910k    0     0  1454k      0 --:--:--  0:00:04 --:--:-- 2012k
7PQTU2BLNNRJX4N5S6ZQKK6FAQCF7XZY
901188
Traceback (most recent call last):
  File "/home/ec2-user/kc_makeStrangle.py", line 94, in place_order
    orderId = kite.place_order(
  File "/home/ec2-user/.local/lib/python3.9/site-packages/kiteconnect/connect.py", line 360, in place_order
    return self._post("order.place",
  File "/home/ec2-user/.local/lib/python3.9/site-packages/kiteconnect/connect.py", line 855, in _post
    return self._request(route, "POST", url_args=url_args, params=params, is_json=is_json, query_params=query_params)
  File "/home/ec2-user/.local/lib/python3.9/site-packages/kiteconnect/connect.py", line 927, in _request
    raise exp(data["message"], code=r.status_code)
kiteconnect.exceptions.InputException: Markets are closed right now. Use GTT for placing long standing orders instead. [Read more.](https://support.zerodha.com/category/trading-and-markets/gtt/articles/what-is-the-good-till-triggered-gtt-feature)

During handling of the above exception, another exception occurred:

Traceback (most recent call last):
  File "/home/ec2-user/kc_makeStrangle.py", line 112, in <module>
    place_order(symbol_ce, 0, quantity, kite.TRANSACTION_TYPE_SELL, KiteConnect.EXCHANGE_NFO, KiteConnect.PRODUCT_NRML, KiteConnect.ORDER_TYPE_MARKET)
  File "/home/ec2-user/kc_makeStrangle.py", line 107, in place_order
    logger.error('Order placement failed: %s', e.message)
AttributeError: 'InputException' object has no attribute 'message'

*************

Mon May 15 03:30:08 UTC 2023
  % Total    % Received % Xferd  Average Speed   Time    Time     Time  Current
                                 Dload  Upload   Total   Spent    Left  Speed
  0     0    0     0    0     0      0      0 --:--:-- --:--:-- --:--:--     0  0     0    0     0    0     0      0      0 --:--:-- --:--:-- --:--:--     0100 6911k    0 6911k    0     0  17.1M      0 --:--:-- --:--:-- --:--:-- 17.0M
7PQTU2BLNNRJX4N5S6ZQKK6FAQCF7XZY
174624
calling make and track straddle
Traceback (most recent call last):
  File "/home/ec2-user/trackPnL.py", line 170, in <module>
    time.sleep(10)
KeyboardInterrupt
calling make and track straddle
calling make and track straddle
called make and track straddle
calling make and track straddle
called make and track straddle
calling make and track straddle
called make and track straddle
calling curl
  % Total    % Received % Xferd  Average Speed   Time    Time     Time  Current
                                 Dload  Upload   Total   Spent    Left  Speed
  0     0    0     0    0     0      0      0 --:--:-- --:--:-- --:--:--     0
*************

Tue May 16 03:30:12 UTC 2023
  0     0    0     0    0     0      0      0 --:--:--  0:00:02 --:--:--     0100 2154k    0 2154k    0     0   599k      0 --:--:--  0:00:03 --:--:--  599k100 6899k    0 6899k    0     0  1488k      0 --:--:--  0:00:04 --:--:-- 1488k100 6944k    0 6944k    0     0  1473k      0 --:--:--  0:00:04 --:--:-- 1473k
done with curl
7PQTU2BLNNRJX4N5S6ZQKK6FAQCF7XZY
648789
calling make and track straddle
called make and track straddle
calling make and track straddle
called make and track straddle
Traceback (most recent call last):
  File "/home/ec2-user/trackPnL.py", line 151, in <module>
    if(PnL > target):
TypeError: '>' not supported between instances of 'float' and 'str'
calling make and track straddle
called make and track straddle
calling make and track straddle
called make and track straddle
calling make and track straddle
called make and track straddle
calling make and track straddle
called make and track straddle
Wed May 17 03:30:05 UTC 2023

*************

calling curl
  % Total    % Received % Xferd  Average Speed   Time    Time     Time  Current
                                 Dload  Upload   Total   Spent    Left  Speed
  0     0    0     0    0     0      0      0 --:--:-- --:--:-- --:--:--     0  0     0    0     0    0     0      0      0 --:--:--  0:00:01 --:--:--     0100 2047k    0 2047k    0     0   854k      0 --:--:--  0:00:02 --:--:--  854k100 6989k    0 6989k    0     0  2536k      0 --:--:--  0:00:02 --:--:-- 2536k
done with curl
7PQTU2BLNNRJX4N5S6ZQKK6FAQCF7XZY
229386
calling make and track straddle
called make and track straddle
calling make and track straddle
called make and track straddle
calling make and track straddle
called make and track straddle
calling make and track straddle
called make and track straddle
calling make and track straddle
called make and track straddle
calling make and track straddle
called make and track straddle
calling make and track straddle
calling make and track straddle
called make and track straddle

*************

Thu May 18 03:30:07 UTC 2023
calling curl
  % Total    % Received % Xferd  Average Speed   Time    Time     Time  Current
                                 Dload  Upload   Total   Spent    Left  Speed
  0     0    0     0    0     0      0      0 --:--:-- --:--:-- --:--:--     0100 4760k    0 4760k    0     0  8202k      0 --:--:-- --:--:-- --:--:-- 8207k100 6996k    0 6996k    0     0  11.1M      0 --:--:-- --:--:-- --:--:-- 11.1M
done with curl
7PQTU2BLNNRJX4N5S6ZQKK6FAQCF7XZY
119400
calling make and track straddle
called make and track straddle
calling make and track straddle
called make and track straddle
calling make and track straddle
called make and track straddle
calling make and track straddle
called make and track straddle
calling make and track straddle
Traceback (most recent call last):
  File "/home/ec2-user/kc_makeStraddle.py", line 1, in <module>
    from kiteconnect import KiteConnect
  File "/home/ec2-user/.local/lib/python3.9/site-packages/kiteconnect/__init__.py", line 112, in <module>
    from kiteconnect.connect import KiteConnect
  File "/home/ec2-user/.local/lib/python3.9/site-packages/kiteconnect/connect.py", line 18, in <module>
    import requests
  File "/usr/lib/python3.9/site-packages/requests/__init__.py", line 43, in <module>
    import urllib3
  File "/usr/local/lib/python3.9/site-packages/urllib3/__init__.py", line 13, in <module>
    from .connectionpool import HTTPConnectionPool, HTTPSConnectionPool, connection_from_url
  File "/usr/local/lib/python3.9/site-packages/urllib3/connectionpool.py", line 39, in <module>
    from .request import RequestMethods
  File "/usr/local/lib/python3.9/site-packages/urllib3/request.py", line 3, in <module>
    from .filepost import encode_multipart_formdata
  File "/usr/local/lib/python3.9/site-packages/urllib3/filepost.py", line 8, in <module>
    from .fields import RequestField
  File "/usr/local/lib/python3.9/site-packages/urllib3/fields.py", line 4, in <module>
    import mimetypes
  File "<frozen importlib._bootstrap>", line 1007, in _find_and_load
  File "<frozen importlib._bootstrap>", line 982, in _find_and_load_unlocked
  File "<frozen importlib._bootstrap>", line 925, in _find_spec
  File "<frozen importlib._bootstrap_external>", line 1423, in find_spec
  File "<frozen importlib._bootstrap_external>", line 1395, in _get_spec
  File "<frozen importlib._bootstrap_external>", line 1555, in find_spec
  File "<frozen importlib._bootstrap_external>", line 156, in _path_isfile
  File "<frozen importlib._bootstrap_external>", line 148, in _path_is_mode_type
  File "<frozen importlib._bootstrap_external>", line 142, in _path_stat
KeyboardInterrupt
calling make and track straddle
called make and track straddle
calling make and track straddle
called make and track straddle
calling make and track straddle
called make and track straddle
calling make and track straddle
called make and track straddle
calling make and track straddle
called make and track straddle
calling make and track straddle
called make and track straddle
calling make and track straddle
called make and track straddle
calling make and track straddle
called make and track straddle
calling make and track straddle
called make and track straddle
calling make and track straddle
called make and track straddle

*************

calling curl
  % Total    % Received % Xferd  Average Speed   Time    Time     Time  Current
                                 Dload  Upload   Total   Spent    Left  Speed
  0     0    0     0    0     0      0      0 --:--:-- --:--:-- --:--:--     0Fri May 19 03:30:12 UTC 2023
  0     0    0     0    0     0      0      0 --:--:--  0:00:02 --:--:--     0100  908k    0  908k    0     0   264k      0 --:--:--  0:00:03 --:--:--  264k100 2762k    0 2762k    0     0   611k      0 --:--:--  0:00:04 --:--:--  611k100 4807k    0 4807k    0     0   884k      0 --:--:--  0:00:05 --:--:--  884k100 7041k    0 7041k    0     0  1151k      0 --:--:--  0:00:06 --:--:-- 1152k
done with curl
7PQTU2BLNNRJX4N5S6ZQKK6FAQCF7XZY
314158
tagret not defined defaulting to 5000
5000
calling make and track straddle
Traceback (most recent call last):
  File "/home/ec2-user/kc_makeStraddle.py", line 57, in <module>
    peToken = (list(peToken)[0])
IndexError: list index out of range
called make and track straddle
Traceback (most recent call last):
  File "/home/ec2-user/trackPnL.py", line 63, in <module>
    peToken = (list(peToken)[0])
IndexError: list index out of range
calling make and track straddle
Traceback (most recent call last):
  File "/home/ec2-user/kc_makeStraddle.py", line 57, in <module>
    peToken = (list(peToken)[0])
IndexError: list index out of range
called make and track straddle
Traceback (most recent call last):
  File "/home/ec2-user/trackPnL.py", line 63, in <module>
    peToken = (list(peToken)[0])
IndexError: list index out of range
calling make and track straddle
Traceback (most recent call last):
  File "/home/ec2-user/kc_makeStraddle.py", line 57, in <module>
    peToken = (list(peToken)[0])
IndexError: list index out of range
called make and track straddle
Traceback (most recent call last):
  File "/home/ec2-user/trackPnL.py", line 63, in <module>
    peToken = (list(peToken)[0])
IndexError: list index out of range
calling make and track straddle
called make and track straddle
calling make and track straddle
called make and track straddle
calling make and track straddle
called make and track straddle
calling make and track straddle
called make and track straddle
calling make and track straddle
called make and track straddle
calling make and track straddle
called make and track straddle
calling make and track straddle
called make and track straddle

*************

Sat May 20 03:30:08 UTC 2023
calling curl
  % Total    % Received % Xferd  Average Speed   Time    Time     Time  Current
                                 Dload  Upload   Total   Spent    Left  Speed
  0     0    0     0    0     0      0      0 --:--:-- --:--:-- --:--:--     0100 7033k    0 7033k    0     0  20.4M      0 --:--:-- --:--:-- --:--:-- 20.5M
done with curl
7PQTU2BLNNRJX4N5S6ZQKK6FAQCF7XZY
359262
tagret not defined defaulting to 5000
5000
calling make and track straddle
called make and track straddle
Traceback (most recent call last):
  File "/home/ec2-user/.local/lib/python3.9/site-packages/mysql/connector/connection_cext.py", line 291, in _open_connection
    self._cmysql.connect(**cnx_kwargs)
_mysql_connector.MySQLInterfaceError: Can't connect to MySQL server on 'database-1.ctiw3pd8unxg.us-east-2.rds.amazonaws.com:3306' (110)

The above exception was the direct cause of the following exception:

Traceback (most recent call last):
  File "/home/ec2-user/trackPnL.py", line 124, in <module>
    connection = mysql.connector.connect(host='database-1.ctiw3pd8unxg.us-east-2.rds.amazonaws.com',
  File "/home/ec2-user/.local/lib/python3.9/site-packages/mysql/connector/pooling.py", line 293, in connect
    return CMySQLConnection(*args, **kwargs)
  File "/home/ec2-user/.local/lib/python3.9/site-packages/mysql/connector/connection_cext.py", line 120, in __init__
    self.connect(**kwargs)
  File "/home/ec2-user/.local/lib/python3.9/site-packages/mysql/connector/abstracts.py", line 1181, in connect
    self._open_connection()
  File "/home/ec2-user/.local/lib/python3.9/site-packages/mysql/connector/connection_cext.py", line 296, in _open_connection
    raise get_mysql_exception(
mysql.connector.errors.DatabaseError: 2003 (HY000): Can't connect to MySQL server on 'database-1.ctiw3pd8unxg.us-east-2.rds.amazonaws.com:3306' (110)

During handling of the above exception, another exception occurred:

Traceback (most recent call last):
  File "/home/ec2-user/trackPnL.py", line 137, in <module>
    except Error as e:
NameError: name 'Error' is not defined

During handling of the above exception, another exception occurred:

Traceback (most recent call last):
  File "/home/ec2-user/trackPnL.py", line 140, in <module>
    if connection.is_connected():
NameError: name 'connection' is not defined
